<?xml version='1.0'?>

<robot name="cpmbot" xmlns:xacro="http://www.ros.org/wiki/xacro">
		
	<xacro:macro name="mecanum_wheel_with_joint" params="parent_name frontal_name pre_name left radius jointX jointY jointZ">

		<xacro:property name="name_side" value="right"/>
		<xacro:property name="reflect_side" value="-1"/>
		<xacro:property name="mecanum_wheel_origin_angle" value="${mecanum_wheel_origin_angle_p} ${mecanum_wheel_origin_angle_r} ${-mecanum_wheel_origin_angle_y}"/>
		<!-- evaluation -->		
		<xacro:if value="${left}">
			<xacro:property name="name_side" value="left"/>
			<xacro:property name="reflect_side" value="1"/>
			<xacro:property name="mecanum_wheel_origin_angle" value="${mecanum_wheel_origin_angle_p} ${mecanum_wheel_origin_angle_r} ${mecanum_wheel_origin_angle_y}"/>			
		</xacro:if>

		<xacro:mecanum_wheel name="${parent_name}_${name_side}_mecanum_wheel" radius="${radius}" origin_angle="${mecanum_wheel_origin_angle}">		
		</xacro:mecanum_wheel>

		<joint type="continuous" name="${pre_name}_${frontal_name}_${name_side}_joint">
			<origin xyz="${jointX} ${reflect_side*jointY} ${jointZ}" rpy="0 0 0"/>
			<child link="${parent_name}_${name_side}_mecanum_wheel"/>
			<parent link="${parent_name}"/>
			<axis xyz="0 1 0" rpy="0 0 0"/>
			<limit effort="100" velocity="100"/>
			<joint_properties damping="0.0" friction="0.0"/>
		</joint>
		<transmission name="${pre_name}_${frontal_name}_${name_side}_joint_trans">
			<type>transmission_interface/SimpleTransmission</type>
			<joint name="${pre_name}_${frontal_name}_${name_side}_joint">
				<hardwareInterface>EffortJointInterface</hardwareInterface>
			</joint>
			<actuator name="${pre_name}_${frontal_name}_${name_side}_joint_motor">
				<hardwareInterface>EffortJointInterface</hardwareInterface>
				<mechanicalReduction>1</mechanicalReduction>
			</actuator>
		</transmission>
	<gazebo reference="${parent_name}_${name_side}_mecanum_wheel">
	        <kp>100000.0</kp>
	        <kd>100000.0</kd>
	        <mu1>0.0</mu1>
	        <mu2>0.</mu2>

	        <fdir1>1 0 0</fdir1>
	        <material>Gazebo/Green</material>
    	</gazebo>
	</xacro:macro>

</robot>
