<?xml version='1.0'?>
<robot name="cpmbot"
    xmlns:xacro="http://www.ros.org/wiki/xacro">
    <xacro:macro name="wheel_with_joint" params="parent_name frontal_name pre_name left radius heigth jointX jointY jointZ">
        <xacro:property name="name_side" value="right"/>
        <xacro:property name="reflect_side" value="-1"/>
        <!-- evaluation -->
        <xacro:if value="${left}">
            <xacro:property name="name_side" value="left"/>
            <xacro:property name="reflect_side" value="1"/>
        </xacro:if>
        <xacro:wheel name="${parent_name}_${name_side}_wheel" radius="${radius}" heigth="${heigth}"></xacro:wheel>
        <joint type="continuous" name="${pre_name}_${frontal_name}_${name_side}_joint">
            <origin xyz="${jointX} ${reflect_side*jointY} ${jointZ}" rpy="0 0 0"/>
            <child link="${parent_name}_${name_side}_wheel"/>
            <parent link="${parent_name}"/>
            <axis xyz="0 1 0" rpy="0 0 0"/>
            <limit effort="100" velocity="100"/>
            <joint_properties damping="0.0" friction="0.0"/>
        </joint>
        <transmission name="${pre_name}_${frontal_name}_${name_side}_joint_trans">
            <type>transmission_interface/SimpleTransmission</type>
            <joint name="${pre_name}_${frontal_name}_${name_side}_joint">
                <hardwareInterface>hardware_interface/EffortJointInterface</hardwareInterface>
            </joint>
            <actuator name="${pre_name}_${frontal_name}_${name_side}_joint_motor">
                <hardwareInterface>hardware_interface/EffortJointInterface</hardwareInterface>
                <mechanicalReduction>1</mechanicalReduction>
            </actuator>
        </transmission>
    </xacro:macro>
</robot>
